<?xml version="1.0" ?>
<!-- =================================================================================== -->
<!-- |    This document was autogenerated by xacro from skid6x6.urdf.xacro             | -->
<!-- |    EDITING THIS FILE BY HAND IS NOT RECOMMENDED                                 | -->
<!-- =================================================================================== -->
<robot name="skid6x6">
  <!-- ========================================================= -->
  <!--                         MATERIALS                         -->
  <!-- ========================================================= -->
  <material name="black">
    <color rgba="0 0 0 1"/>
  </material>
  <material name="grey">
    <color rgba="0.5 0.5 0.5 1"/>
  </material>
  <!-- Front LiDAR -->
  <gazebo reference="lidar_front_frame">
    <sensor name="velodyne-HDL32E" type="gpu_ray">
      <pose>0 0 0 0 0 0</pose>
      <visualize>false</visualize>
      <update_rate>100.0</update_rate>
      <ray>
        <scan>
          <horizontal>
            <samples>2187</samples>
            <resolution>1</resolution>
            <min_angle>-1.5708</min_angle>
            <max_angle>1.5708</max_angle>
          </horizontal>
          <vertical>
            <samples>32</samples>
            <resolution>1</resolution>
            <min_angle>-0.535</min_angle>
            <max_angle>0.186</max_angle>
          </vertical>
        </scan>
        <range>
          <min>0.3</min>
          <max>131.0</max>
          <resolution>0.001</resolution>
        </range>
        <noise>
          <type>gaussian</type>
          <mean>0.0</mean>
          <stddev>0.0</stddev>
        </noise>
      </ray>
      <plugin filename="libgazebo_ros_velodyne_laser.so" name="front_laserscan">
        <ros>
          <remapping>~/out:=scan/front</remapping>
          <argument>use_sim_time:=true</argument>
        </ros>
        <organize_cloud>true</organize_cloud>
        <frame_name>lidar_front_frame</frame_name>
        <min_range>0.9</min_range>
        <max_range>30.0</max_range>
        <gaussian_noise>0.008</gaussian_noise>
      </plugin>
    </sensor>
  </gazebo>
  <!-- REAR LiDAR -->
  <gazebo reference="lidar_rear_frame">
    <sensor name="velodyne2-HDL32E" type="ray">
      <pose>0 0 0 0 0 0</pose>
      <visualize>false</visualize>
      <update_rate>100.0</update_rate>
      <ray>
        <scan>
          <horizontal>
            <samples>2187</samples>
            <resolution>1</resolution>
            <min_angle>-1.5708</min_angle>
            <max_angle>1.5708</max_angle>
          </horizontal>
          <vertical>
            <samples>32</samples>
            <resolution>1</resolution>
            <min_angle>-0.535</min_angle>
            <max_angle>0.186</max_angle>
          </vertical>
        </scan>
        <range>
          <min>0.3</min>
          <max>131.0</max>
          <resolution>0.001</resolution>
        </range>
        <noise>
          <type>gaussian</type>
          <mean>0.0</mean>
          <stddev>0.0</stddev>
        </noise>
      </ray>
      <plugin filename="libgazebo_ros_velodyne_laser.so" name="gazebo_ros_laser_controller">
        <ros>
          <remapping>~/out:=scan/rear</remapping>
        </ros>
        <frame_name>lidar_rear_frame</frame_name>
        <organize_cloud>false</organize_cloud>
        <min_range>0.9</min_range>
        <max_range>130.0</max_range>
        <gaussian_noise>0.008</gaussian_noise>
      </plugin>
    </sensor>
  </gazebo>
  <!-- DIFF DRIVE CONTROLLER -->
  <gazebo>
    <plugin filename="libgazebo_ros_diff_drive.so" name="wheel_drive_controller">
      <!-- Wheel joints -->
      <num_wheel_pairs>3</num_wheel_pairs>
      <left_joint>left_front_wheel_joint</left_joint>
      <left_joint>left_mid_wheel_joint</left_joint>
      <left_joint>left_rear_wheel_joint</left_joint>
      <right_joint>right_front_wheel_joint</right_joint>
      <right_joint>right_mid_wheel_joint</right_joint>
      <right_joint>right_rear_wheel_joint</right_joint>
      <!-- Kinematics -->
      <wheel_separation>0.64</wheel_separation>
      <wheel_diameter>0.12</wheel_diameter>
      <!-- Dynamics -->
      <max_wheel_torque>200.0</max_wheel_torque>
      <max_wheel_acceleration>10.0</max_wheel_acceleration>
      <!-- Frames -->
      <odometry_frame>odom</odometry_frame>
      <robot_base_frame>base_link</robot_base_frame>
      <!-- ROS integration -->
      <ros>
        <namespace>/</namespace>
        <!-- <use_sim_time>true</use_sim_time> -->
        <argument>use_sim_time:=true</argument>
        <argument>/cmd_vel:=cmd_vel</argument>
        <argument>/odom:=odom</argument>
      </ros>
      <!-- Odometry and TF -->
      <publish_odom>true</publish_odom>
      <!-- <publish_odom_tf>true</publish_odom_tf> -->
      <!-- <publish_delay>0.05</publish_delay> -->
      <update_rate>100.0</update_rate>
      <!-- Keep same as LiDAR rate -->
    </plugin>
  </gazebo>
  <!-- Add friction to all wheels -->
  <gazebo reference="left_front_wheel_link">
    <mu1>1.0</mu1>
    <mu2>1.0</mu2>
  </gazebo>
  <gazebo reference="left_mid_wheel_link">
    <mu1>1.0</mu1>
    <mu2>1.0</mu2>
  </gazebo>
  <gazebo reference="left_rear_wheel_link">
    <mu1>1.0</mu1>
    <mu2>1.0</mu2>
  </gazebo>
  <gazebo reference="right_front_wheel_link">
    <mu1>1.0</mu1>
    <mu2>1.0</mu2>
  </gazebo>
  <gazebo reference="right_mid_wheel_link">
    <mu1>1.0</mu1>
    <mu2>1.0</mu2>
  </gazebo>
  <gazebo reference="right_rear_wheel_link">
    <mu1>1.0</mu1>
    <mu2>1.0</mu2>
  </gazebo>
  <!-- ========================================================= -->
  <!--                         BASE LINK                         -->
  <!-- ========================================================= -->
  <link name="base_link">
    <visual>
      <geometry>
        <box size="0.8 0.6 0.3"/>
      </geometry>
      <origin xyz="0 0 0.15"/>
      <material name="grey"/>
    </visual>
    <collision>
      <geometry>
        <box size="0.8 0.6 0.3"/>
      </geometry>
      <origin xyz="0 0 0.15"/>
    </collision>
    <inertial>
      <mass value="10.0"/>
      <origin xyz="0 0 0.15"/>
      <inertia ixx="0.2" ixy="0.0" ixz="0.0" iyy="0.3" iyz="0.0" izz="0.4"/>
    </inertial>
  </link>
  <gazebo reference="base_link">
    <material>Gazebo/White</material>
  </gazebo>
  <link name="left_front_wheel_link">
    <visual>
      <geometry>
        <cylinder length="0.05" radius="0.12"/>
      </geometry>
      <origin rpy="0 1.5708 0" xyz="0 0 0"/>
      <material name="black"/>
    </visual>
    <collision>
      <geometry>
        <cylinder length="0.05" radius="0.12"/>
      </geometry>
      <origin rpy="0 1.5708 0" xyz="0 0 0"/>
    </collision>
    <inertial>
      <mass value="0.5"/>
      <origin xyz="0 0 0"/>
      <inertia ixx="0.001" ixy="0.0" ixz="0.0" iyy="0.001" iyz="0.0" izz="0.001"/>
    </inertial>
  </link>
  <joint name="left_front_wheel_joint" type="continuous">
    <parent link="base_link"/>
    <child link="left_front_wheel_link"/>
    <origin rpy="0 0 1.57" xyz="0.3 0.32 0.06"/>
    <axis xyz="1 0 0"/>
  </joint>
  <gazebo reference="left_front_wheel_link">
    <material>Gazebo/Black</material>
    <mu1>1.0</mu1>
    <mu2>1.0</mu2>
  </gazebo>
  <link name="left_mid_wheel_link">
    <visual>
      <geometry>
        <cylinder length="0.05" radius="0.12"/>
      </geometry>
      <origin rpy="0 1.5708 0" xyz="0 0 0"/>
      <material name="black"/>
    </visual>
    <collision>
      <geometry>
        <cylinder length="0.05" radius="0.12"/>
      </geometry>
      <origin rpy="0 1.5708 0" xyz="0 0 0"/>
    </collision>
    <inertial>
      <mass value="0.5"/>
      <origin xyz="0 0 0"/>
      <inertia ixx="0.001" ixy="0.0" ixz="0.0" iyy="0.001" iyz="0.0" izz="0.001"/>
    </inertial>
  </link>
  <joint name="left_mid_wheel_joint" type="continuous">
    <parent link="base_link"/>
    <child link="left_mid_wheel_link"/>
    <origin rpy="0 0 1.57" xyz="0.0 0.32 0.06"/>
    <axis xyz="1 0 0"/>
  </joint>
  <gazebo reference="left_mid_wheel_link">
    <material>Gazebo/Black</material>
    <mu1>1.0</mu1>
    <mu2>1.0</mu2>
  </gazebo>
  <link name="left_rear_wheel_link">
    <visual>
      <geometry>
        <cylinder length="0.05" radius="0.12"/>
      </geometry>
      <origin rpy="0 1.5708 0" xyz="0 0 0"/>
      <material name="black"/>
    </visual>
    <collision>
      <geometry>
        <cylinder length="0.05" radius="0.12"/>
      </geometry>
      <origin rpy="0 1.5708 0" xyz="0 0 0"/>
    </collision>
    <inertial>
      <mass value="0.5"/>
      <origin xyz="0 0 0"/>
      <inertia ixx="0.001" ixy="0.0" ixz="0.0" iyy="0.001" iyz="0.0" izz="0.001"/>
    </inertial>
  </link>
  <joint name="left_rear_wheel_joint" type="continuous">
    <parent link="base_link"/>
    <child link="left_rear_wheel_link"/>
    <origin rpy="0 0 1.57" xyz="-0.3 0.32 0.06"/>
    <axis xyz="1 0 0"/>
  </joint>
  <gazebo reference="left_rear_wheel_link">
    <material>Gazebo/Black</material>
    <mu1>1.0</mu1>
    <mu2>1.0</mu2>
  </gazebo>
  <link name="right_front_wheel_link">
    <visual>
      <geometry>
        <cylinder length="0.05" radius="0.12"/>
      </geometry>
      <origin rpy="0 1.5708 0" xyz="0 0 0"/>
      <material name="black"/>
    </visual>
    <collision>
      <geometry>
        <cylinder length="0.05" radius="0.12"/>
      </geometry>
      <origin rpy="0 1.5708 0" xyz="0 0 0"/>
    </collision>
    <inertial>
      <mass value="0.5"/>
      <origin xyz="0 0 0"/>
      <inertia ixx="0.001" ixy="0.0" ixz="0.0" iyy="0.001" iyz="0.0" izz="0.001"/>
    </inertial>
  </link>
  <joint name="right_front_wheel_joint" type="continuous">
    <parent link="base_link"/>
    <child link="right_front_wheel_link"/>
    <origin rpy="0 0 1.57" xyz="0.3 -0.32 0.06"/>
    <axis xyz="1 0 0"/>
  </joint>
  <gazebo reference="right_front_wheel_link">
    <material>Gazebo/Black</material>
    <mu1>1.0</mu1>
    <mu2>1.0</mu2>
  </gazebo>
  <link name="right_mid_wheel_link">
    <visual>
      <geometry>
        <cylinder length="0.05" radius="0.12"/>
      </geometry>
      <origin rpy="0 1.5708 0" xyz="0 0 0"/>
      <material name="black"/>
    </visual>
    <collision>
      <geometry>
        <cylinder length="0.05" radius="0.12"/>
      </geometry>
      <origin rpy="0 1.5708 0" xyz="0 0 0"/>
    </collision>
    <inertial>
      <mass value="0.5"/>
      <origin xyz="0 0 0"/>
      <inertia ixx="0.001" ixy="0.0" ixz="0.0" iyy="0.001" iyz="0.0" izz="0.001"/>
    </inertial>
  </link>
  <joint name="right_mid_wheel_joint" type="continuous">
    <parent link="base_link"/>
    <child link="right_mid_wheel_link"/>
    <origin rpy="0 0 1.57" xyz="0.0 -0.32 0.06"/>
    <axis xyz="1 0 0"/>
  </joint>
  <gazebo reference="right_mid_wheel_link">
    <material>Gazebo/Black</material>
    <mu1>1.0</mu1>
    <mu2>1.0</mu2>
  </gazebo>
  <link name="right_rear_wheel_link">
    <visual>
      <geometry>
        <cylinder length="0.05" radius="0.12"/>
      </geometry>
      <origin rpy="0 1.5708 0" xyz="0 0 0"/>
      <material name="black"/>
    </visual>
    <collision>
      <geometry>
        <cylinder length="0.05" radius="0.12"/>
      </geometry>
      <origin rpy="0 1.5708 0" xyz="0 0 0"/>
    </collision>
    <inertial>
      <mass value="0.5"/>
      <origin xyz="0 0 0"/>
      <inertia ixx="0.001" ixy="0.0" ixz="0.0" iyy="0.001" iyz="0.0" izz="0.001"/>
    </inertial>
  </link>
  <joint name="right_rear_wheel_joint" type="continuous">
    <parent link="base_link"/>
    <child link="right_rear_wheel_link"/>
    <origin rpy="0 0 1.57" xyz="-0.3 -0.32 0.06"/>
    <axis xyz="1 0 0"/>
  </joint>
  <gazebo reference="right_rear_wheel_link">
    <material>Gazebo/Black</material>
    <mu1>1.0</mu1>
    <mu2>1.0</mu2>
  </gazebo>
  <!-- ========================================================= -->
  <!--                      FRONT LiDAR                          -->
  <!-- ========================================================= -->
  <link name="lidar_front_link">
    <visual>
      <geometry>
        <box size="0.1 0.1 0.05"/>
      </geometry>
      <origin xyz="0 0 0.025"/>
      <material name="black"/>
    </visual>
    <collision>
      <geometry>
        <box size="0.1 0.1 0.05"/>
      </geometry>
      <origin xyz="0 0 0.025"/>
    </collision>
    <inertial>
      <mass value="0.1"/>
      <origin xyz="0 0 0"/>
      <inertia ixx="0.0001" ixy="0.0" ixz="0.0" iyy="0.0001" iyz="0.0" izz="0.0001"/>
    </inertial>
  </link>
  <joint name="lidar_front_joint" type="fixed">
    <parent link="base_link"/>
    <child link="lidar_front_link"/>
    <origin rpy="0 0 0" xyz="0.35 0 0.3"/>
  </joint>
  <gazebo reference="lidar_front_link">
    <material>Gazebo/Black</material>
  </gazebo>
  <link name="lidar_front_frame"/>
  <joint name="lidar_front_frame_joint" type="fixed">
    <parent link="lidar_front_link"/>
    <child link="lidar_front_frame"/>
    <origin rpy="0 0 0" xyz="0.05 0 0.05"/>
  </joint>
  <!-- ========================================================= -->
  <!--                      REAR LiDAR                           -->
  <!-- ========================================================= -->
  <link name="lidar_rear_link">
    <visual>
      <geometry>
        <box size="0.1 0.4 0.05"/>
      </geometry>
      <origin xyz="0 0 0.025"/>
      <material name="black"/>
    </visual>
    <collision>
      <geometry>
        <box size="0.1 0.1 0.05"/>
      </geometry>
      <origin xyz="0 0 0.025"/>
    </collision>
    <inertial>
      <mass value="0.1"/>
      <origin xyz="0 0 0"/>
      <inertia ixx="0.0001" ixy="0.0" ixz="0.0" iyy="0.0001" iyz="0.0" izz="0.0001"/>
    </inertial>
  </link>
  <joint name="lidar_rear_joint" type="fixed">
    <parent link="base_link"/>
    <child link="lidar_rear_link"/>
    <origin rpy="0 0 3.14" xyz="-0.35 0 0.3"/>
  </joint>
  <gazebo reference="lidar_rear_link">
    <material>Gazebo/Black</material>
  </gazebo>
  <link name="lidar_rear_frame"/>
  <joint name="lidar_rear_frame_joint" type="fixed">
    <parent link="lidar_rear_link"/>
    <child link="lidar_rear_frame"/>
    <origin rpy="0 0 0" xyz="0.05 0 0.05"/>
  </joint>
</robot>
